2024-06-17 17:38:02,212 INFO    MainThread:3818 [wandb_setup.py:_flush():76] Current SDK version is 0.17.1
2024-06-17 17:38:02,212 INFO    MainThread:3818 [wandb_setup.py:_flush():76] Configure stats pid to 3818
2024-06-17 17:38:02,212 INFO    MainThread:3818 [wandb_setup.py:_flush():76] Loading settings from /home/ali/.config/wandb/settings
2024-06-17 17:38:02,212 INFO    MainThread:3818 [wandb_setup.py:_flush():76] Loading settings from /home/ali/tum/i2dl/exercise/i2dl/exercise_09/wandb/settings
2024-06-17 17:38:02,212 INFO    MainThread:3818 [wandb_setup.py:_flush():76] Loading settings from environment variables: {}
2024-06-17 17:38:02,212 INFO    MainThread:3818 [wandb_setup.py:_flush():76] Applying setup settings: {'_disable_service': False}
2024-06-17 17:38:02,212 INFO    MainThread:3818 [wandb_setup.py:_flush():76] Inferring run settings from compute environment: {'program': '<python with no main file>'}
2024-06-17 17:38:02,212 INFO    MainThread:3818 [wandb_setup.py:_flush():76] Applying login settings: {}
2024-06-17 17:38:02,213 INFO    MainThread:3818 [wandb_init.py:_log_setup():520] Logging user logs to /home/ali/tum/i2dl/exercise/i2dl/exercise_09/wandb/run-20240617_173802-fixof9j8/logs/debug.log
2024-06-17 17:38:02,213 INFO    MainThread:3818 [wandb_init.py:_log_setup():521] Logging internal logs to /home/ali/tum/i2dl/exercise/i2dl/exercise_09/wandb/run-20240617_173802-fixof9j8/logs/debug-internal.log
2024-06-17 17:38:02,213 INFO    MainThread:3818 [wandb_init.py:_jupyter_setup():466] configuring jupyter hooks <wandb.sdk.wandb_init._WandbInit object at 0x7e0707ed5f90>
2024-06-17 17:38:02,213 INFO    MainThread:3818 [wandb_init.py:init():560] calling init triggers
2024-06-17 17:38:02,213 INFO    MainThread:3818 [wandb_init.py:init():567] wandb.init called with sweep_config: {}
config: {'hidden_dim': 1, 'num_hidden_linear': 50, 'epochs': 3, 'batchsize': 40, 'learning_rate': 0.0001}
2024-06-17 17:38:02,213 INFO    MainThread:3818 [wandb_init.py:init():585] re-initializing run, found existing run on stack: ys7gect3
2024-06-17 17:38:02,214 ERROR   MainThread:3818 [wandb_init.py:init():1181] error in wandb.init()
Traceback (most recent call last):
  File "/home/ali/miniconda3/envs/i2dl/lib/python3.11/site-packages/wandb/sdk/wandb_init.py", line 1171, in init
    return wi.init()
           ^^^^^^^^^
  File "/home/ali/miniconda3/envs/i2dl/lib/python3.11/site-packages/wandb/sdk/wandb_init.py", line 595, in init
    latest_run.finish()
  File "/home/ali/miniconda3/envs/i2dl/lib/python3.11/site-packages/wandb/sdk/wandb_run.py", line 449, in wrapper
    return func(self, *args, **kwargs)
           ^^^^^^^^^^^^^^^^^^^^^^^^^^^
  File "/home/ali/miniconda3/envs/i2dl/lib/python3.11/site-packages/wandb/sdk/wandb_run.py", line 390, in wrapper
    return func(self, *args, **kwargs)
           ^^^^^^^^^^^^^^^^^^^^^^^^^^^
  File "/home/ali/miniconda3/envs/i2dl/lib/python3.11/site-packages/wandb/sdk/wandb_run.py", line 2100, in finish
    return self._finish(exit_code, quiet)
           ^^^^^^^^^^^^^^^^^^^^^^^^^^^^^^
  File "/home/ali/miniconda3/envs/i2dl/lib/python3.11/site-packages/wandb/sdk/wandb_run.py", line 2107, in _finish
    with telemetry.context(run=self) as tel:
  File "/home/ali/miniconda3/envs/i2dl/lib/python3.11/site-packages/wandb/sdk/lib/telemetry.py", line 42, in __exit__
    self._run._telemetry_callback(self._obj)
  File "/home/ali/miniconda3/envs/i2dl/lib/python3.11/site-packages/wandb/sdk/wandb_run.py", line 798, in _telemetry_callback
    self._telemetry_flush()
  File "/home/ali/miniconda3/envs/i2dl/lib/python3.11/site-packages/wandb/sdk/wandb_run.py", line 809, in _telemetry_flush
    self._backend.interface._publish_telemetry(self._telemetry_obj)
  File "/home/ali/miniconda3/envs/i2dl/lib/python3.11/site-packages/wandb/sdk/interface/interface_shared.py", line 101, in _publish_telemetry
    self._publish(rec)
  File "/home/ali/miniconda3/envs/i2dl/lib/python3.11/site-packages/wandb/sdk/interface/interface_sock.py", line 51, in _publish
    self._sock_client.send_record_publish(record)
  File "/home/ali/miniconda3/envs/i2dl/lib/python3.11/site-packages/wandb/sdk/lib/sock_client.py", line 221, in send_record_publish
    self.send_server_request(server_req)
  File "/home/ali/miniconda3/envs/i2dl/lib/python3.11/site-packages/wandb/sdk/lib/sock_client.py", line 155, in send_server_request
    self._send_message(msg)
  File "/home/ali/miniconda3/envs/i2dl/lib/python3.11/site-packages/wandb/sdk/lib/sock_client.py", line 152, in _send_message
    self._sendall_with_error_handle(header + data)
  File "/home/ali/miniconda3/envs/i2dl/lib/python3.11/site-packages/wandb/sdk/lib/sock_client.py", line 130, in _sendall_with_error_handle
    sent = self._sock.send(data)
           ^^^^^^^^^^^^^^^^^^^^^
BrokenPipeError: [Errno 32] Broken pipe
2024-06-17 17:38:04,384 ERROR   MainThread:3818 [wandb_init.py:init():1181] error in wandb.init()
Traceback (most recent call last):
  File "/home/ali/miniconda3/envs/i2dl/lib/python3.11/site-packages/wandb/sdk/wandb_init.py", line 1170, in init
    wi.setup(kwargs)
  File "/home/ali/miniconda3/envs/i2dl/lib/python3.11/site-packages/wandb/sdk/wandb_init.py", line 219, in setup
    with telemetry.context(obj=self._init_telemetry_obj) as tel:
  File "/home/ali/miniconda3/envs/i2dl/lib/python3.11/site-packages/wandb/sdk/lib/telemetry.py", line 42, in __exit__
    self._run._telemetry_callback(self._obj)
  File "/home/ali/miniconda3/envs/i2dl/lib/python3.11/site-packages/wandb/sdk/wandb_run.py", line 798, in _telemetry_callback
    self._telemetry_flush()
  File "/home/ali/miniconda3/envs/i2dl/lib/python3.11/site-packages/wandb/sdk/wandb_run.py", line 809, in _telemetry_flush
    self._backend.interface._publish_telemetry(self._telemetry_obj)
  File "/home/ali/miniconda3/envs/i2dl/lib/python3.11/site-packages/wandb/sdk/interface/interface_shared.py", line 101, in _publish_telemetry
    self._publish(rec)
  File "/home/ali/miniconda3/envs/i2dl/lib/python3.11/site-packages/wandb/sdk/interface/interface_sock.py", line 51, in _publish
    self._sock_client.send_record_publish(record)
  File "/home/ali/miniconda3/envs/i2dl/lib/python3.11/site-packages/wandb/sdk/lib/sock_client.py", line 221, in send_record_publish
    self.send_server_request(server_req)
  File "/home/ali/miniconda3/envs/i2dl/lib/python3.11/site-packages/wandb/sdk/lib/sock_client.py", line 155, in send_server_request
    self._send_message(msg)
  File "/home/ali/miniconda3/envs/i2dl/lib/python3.11/site-packages/wandb/sdk/lib/sock_client.py", line 152, in _send_message
    self._sendall_with_error_handle(header + data)
  File "/home/ali/miniconda3/envs/i2dl/lib/python3.11/site-packages/wandb/sdk/lib/sock_client.py", line 130, in _sendall_with_error_handle
    sent = self._sock.send(data)
           ^^^^^^^^^^^^^^^^^^^^^
BrokenPipeError: [Errno 32] Broken pipe
2024-06-17 17:38:09,346 ERROR   MainThread:3818 [wandb_init.py:init():1181] error in wandb.init()
Traceback (most recent call last):
  File "/home/ali/miniconda3/envs/i2dl/lib/python3.11/site-packages/wandb/sdk/wandb_init.py", line 1170, in init
    wi.setup(kwargs)
  File "/home/ali/miniconda3/envs/i2dl/lib/python3.11/site-packages/wandb/sdk/wandb_init.py", line 219, in setup
    with telemetry.context(obj=self._init_telemetry_obj) as tel:
  File "/home/ali/miniconda3/envs/i2dl/lib/python3.11/site-packages/wandb/sdk/lib/telemetry.py", line 42, in __exit__
    self._run._telemetry_callback(self._obj)
  File "/home/ali/miniconda3/envs/i2dl/lib/python3.11/site-packages/wandb/sdk/wandb_run.py", line 798, in _telemetry_callback
    self._telemetry_flush()
  File "/home/ali/miniconda3/envs/i2dl/lib/python3.11/site-packages/wandb/sdk/wandb_run.py", line 809, in _telemetry_flush
    self._backend.interface._publish_telemetry(self._telemetry_obj)
  File "/home/ali/miniconda3/envs/i2dl/lib/python3.11/site-packages/wandb/sdk/interface/interface_shared.py", line 101, in _publish_telemetry
    self._publish(rec)
  File "/home/ali/miniconda3/envs/i2dl/lib/python3.11/site-packages/wandb/sdk/interface/interface_sock.py", line 51, in _publish
    self._sock_client.send_record_publish(record)
  File "/home/ali/miniconda3/envs/i2dl/lib/python3.11/site-packages/wandb/sdk/lib/sock_client.py", line 221, in send_record_publish
    self.send_server_request(server_req)
  File "/home/ali/miniconda3/envs/i2dl/lib/python3.11/site-packages/wandb/sdk/lib/sock_client.py", line 155, in send_server_request
    self._send_message(msg)
  File "/home/ali/miniconda3/envs/i2dl/lib/python3.11/site-packages/wandb/sdk/lib/sock_client.py", line 152, in _send_message
    self._sendall_with_error_handle(header + data)
  File "/home/ali/miniconda3/envs/i2dl/lib/python3.11/site-packages/wandb/sdk/lib/sock_client.py", line 130, in _sendall_with_error_handle
    sent = self._sock.send(data)
           ^^^^^^^^^^^^^^^^^^^^^
BrokenPipeError: [Errno 32] Broken pipe
